Workbook

Sheet Price
A1: Product | B1: Mill Finish (₹/ft2) | C1: Mill Finish (₹/m2) | D1: Mill Finish (₹/m) | E1: Powder Coating (₹/ft2) | F1: Powder Coating (₹/m2) | G1: Powder Coating (₹/m) | H1: PVDF (₹/ft2) | I1: PVDF (₹/m2) | J1: PVDF (₹/m)
A2: Profile | B2: =CEILING((C2/10.7639104),10) -> 510 | C2: =((1000/B6)*'Per m weight'!C35)*A6 -> 5444.4444 | D2: =+A6*'Per m weight'!C35 -> 735 | E2: 810 | F2: =C2+(((('Per m weight'!D35/25.4)*39.37)*(1000/B6))*0.25*1.4) -> 6248.1481 | G2: =+D2+((('Per m weight'!D35/25.4)*39.3701)*0.25) -> 812.5002 | H2: 890 | I2: =C2+(((('Per m weight'!D35/25.4)*39.37)*(1000/B6))*0.45*1.4) -> 6891.1111 | J2: =+D2+((('Per m weight'!D35/25.4)*39.3701)*0.6) -> 921.00047
A3: Total Rate (₹) | B3: =SUM(B2:B2) -> 510 | C3: =SUM(C2:C2) -> 5444.4444 | E3: =SUM(E2:E2) -> 810 | F3: =SUM(F2:F2) -> 6248.1481 | H3: =SUM(H2:H2) -> 890 | I3: =SUM(I2:I2) -> 6891.1111
A5: Conversion Rate | B5: Pitch
A6: 750 | B6: 135

Sheet Per m weight
A1: Correct Weight 2020
B2: Product Description | C2: Weight (kg/m) | D2: Perimeter (mm)
A3: LOUVERS | B3: Grille 2050 | C3: 0.373 | D3: 130 | F3: Powder Coating Rate (Rs./in2) | H3: 0.25
B4: Grille 2550 | C4: 0.406 | D4: 140 | F4: Wood Finish Rate (Rs./in2) | H4: 0.6
B5: Grille Carrier | C5: 0.313 | D5: 115
B6: Grille Covering | C6: 0.113 | D6: 40
B7: S Louvers | C7: 0.432 | D7: 120 | E7: Single side coating
D8: 160 | E8: Both side coating | L8: =+F8+((('Per m weight'!D10/25.4)*39.37008)*'Per m weight'!#REF!) -> #REF!
B9: S Louvers Carrier | C9: 1.3 | D9: 410
B10: Aerofoil AF 63/16 | C10: 0.557 | D10: 136
B11: Aerofoil AF 100/20 | C11: 1.082 | D11: 206
B12: Aerofoil AF 120/30 | C12: 1.326 | D12: 251
B13: Aerofoil AF 150/40 | C13: 1.616 | D13: 315
B14: Aerofoil AF 200/50 | C14: 2.8 | D14: 418
B15: Aerofoil AF 200/60 | C15: 2.821 | D15: 425
B16: Aerofoil AF 250/50 | C16: 2.904 | D16: 520
B17: Aerofoil AF 400/60 | C17: 1.787 | D17: 323
B18: Aerofoil Center Piece AF 400/60-C | C18: 1.646 | D18: 183
B19: C Profile For Aerofoil | C19: 1 | D19: 132
B20: Aerofoil Wall Bracket WB (for Aerofoil AF100/20, AF150/40, AF200/50, AF 250/50) | C20: 1.084 | D20: 260 | F20: =+C20/1000 -> 0.001084 | G20: =+F20*150 -> 0.1626 | H20: =+D20*0.15 -> 39
B21: Aerofoil Carrier C1 (AF100/20) | C21: 0.994 | D21: 118
B22: Aerofoil Carrier C2 (AF150/40, AF200/50, AF 250/50) | C22: 1.365 | D22: 166
B23: Half Aerofoil HAF80 | C23: 1 | D23: 177.5
B24: Half Aerofoil HAF120 | C24: 1.342 | D24: 251.5
B25: Half Aerofoil Carrier HAF-C1 (option 1) | C25: 0.358 | D25: =4*25.4 -> 101.6
B26: Half Aerofoil Carrier HAF-C2 (option 2) | C26: 0.438 | D26: =4*25.4 -> 101.6
B27: C Louvers CL113 | C27: 0.62 | D27: 265
B28: C Louvers Carrier CL113-C | C28: 2.544 | D28: 436
B29: C Louvers Carrier Covering CL113-CC | C29: 0.369 | D29: 40
B30: C Louvers CL230 | C30: 1.922 | D30: 525
B31: C Louvers Carrier CL230-C | C31: 5.593 | D31: 580
B32: C Louvers Carrier Covering CL230-CC | C32: 0.283 | D32: 36.5
B33: Rectangular Profile RP 50/124 | C33: 1.444 | D33: =14*25.4 -> 355.6
B34: Rectangular Carrier | C34: 0.761 | D34: =5*25.4 -> 127
B35: Cottal 130 | C35: 0.98 | D35: 200 | E35: Single side coating
B36: Fluted | C36: 1.3 | D36: 275 | E36: Single side coating
B37: 50x50 Profile | D37: 150
B38: 50x50 Carrier | D38: 150
B39: 25x50 Profile | D39: 125
B40: 25x50 carrier | D40: 125
...
